[2024-01-13T15:38:52.423+0200] {taskinstance.py:1957} INFO - Dependencies all met for dep_context=non-requeueable deps ti=<TaskInstance: DAG-USER-DATA-TRANSFER.ETL_USER_DATA manual__2024-01-13T13:38:42.543047+00:00 [queued]>
[2024-01-13T15:38:52.427+0200] {taskinstance.py:1957} INFO - Dependencies all met for dep_context=requeueable deps ti=<TaskInstance: DAG-USER-DATA-TRANSFER.ETL_USER_DATA manual__2024-01-13T13:38:42.543047+00:00 [queued]>
[2024-01-13T15:38:52.427+0200] {taskinstance.py:2171} INFO - Starting attempt 1 of 1
[2024-01-13T15:38:52.437+0200] {taskinstance.py:2192} INFO - Executing <Task(_PythonDecoratedOperator): ETL_USER_DATA> on 2024-01-13 13:38:42.543047+00:00
[2024-01-13T15:38:52.442+0200] {standard_task_runner.py:60} INFO - Started process 44058 to run task
[2024-01-13T15:38:52.448+0200] {standard_task_runner.py:87} INFO - Running: ['airflow', 'tasks', 'run', 'DAG-USER-DATA-TRANSFER', 'ETL_USER_DATA', 'manual__2024-01-13T13:38:42.543047+00:00', '--job-id', '36', '--raw', '--subdir', 'DAGS_FOLDER/users_dag.py', '--cfg-path', '/var/folders/4w/cqlcl4gn3lz6wkw0qjydjq9c0000gq/T/tmpi97abn_a']
[2024-01-13T15:38:52.451+0200] {standard_task_runner.py:88} INFO - Job 36: Subtask ETL_USER_DATA
[2024-01-13T15:38:52.505+0200] {task_command.py:423} INFO - Running <TaskInstance: DAG-USER-DATA-TRANSFER.ETL_USER_DATA manual__2024-01-13T13:38:42.543047+00:00 [running]> on host TLV-02DN0GXP3YW
[2024-01-13T15:38:52.579+0200] {taskinstance.py:2481} INFO - Exporting env vars: AIRFLOW_CTX_DAG_OWNER='airflow' AIRFLOW_CTX_DAG_ID='DAG-USER-DATA-TRANSFER' AIRFLOW_CTX_TASK_ID='ETL_USER_DATA' AIRFLOW_CTX_EXECUTION_DATE='2024-01-13T13:38:42.543047+00:00' AIRFLOW_CTX_TRY_NUMBER='1' AIRFLOW_CTX_DAG_RUN_ID='manual__2024-01-13T13:38:42.543047+00:00'
[2024-01-13T15:38:56.084+0200] {logging_mixin.py:188} INFO - INSERT INTO DIM_USER VALUES (1, 'John Doe', '123-456-7890')
[2024-01-13T15:38:56.269+0200] {taskinstance.py:2699} ERROR - Task failed with exception
Traceback (most recent call last):
  File "/Library/Frameworks/Python.framework/Versions/3.10/lib/python3.10/site-packages/airflow/models/taskinstance.py", line 433, in _execute_task
    result = execute_callable(context=context, **execute_callable_kwargs)
  File "/Library/Frameworks/Python.framework/Versions/3.10/lib/python3.10/site-packages/airflow/decorators/base.py", line 242, in execute
    return_value = super().execute(context)
  File "/Library/Frameworks/Python.framework/Versions/3.10/lib/python3.10/site-packages/airflow/operators/python.py", line 199, in execute
    return_value = self.execute_callable()
  File "/Library/Frameworks/Python.framework/Versions/3.10/lib/python3.10/site-packages/airflow/operators/python.py", line 216, in execute_callable
    return self.python_callable(*self.op_args, **self.op_kwargs)
  File "/Users/angel.georgiev/airflow/dags/users_dag.py", line 24, in etl_transfer_data
    app.execute_load()
  File "/Users/angel.georgiev/airflow/dags/ETLProcess/app.py", line 10, in execute_load
    load_to_table("DIM_USER", "oracle", modified_users_df)
  File "/Users/angel.georgiev/airflow/dags/ETLProcess/db_connector.py", line 83, in load_to_table
    cursor.execute(query)
cx_Oracle.IntegrityError: ORA-00001: unique constraint (ADMIN.SYS_C005964) violated
[2024-01-13T15:38:56.279+0200] {taskinstance.py:1138} INFO - Marking task as FAILED. dag_id=DAG-USER-DATA-TRANSFER, task_id=ETL_USER_DATA, execution_date=20240113T133842, start_date=20240113T133852, end_date=20240113T133856
[2024-01-13T15:38:56.289+0200] {standard_task_runner.py:107} ERROR - Failed to execute job 36 for task ETL_USER_DATA (ORA-00001: unique constraint (ADMIN.SYS_C005964) violated; 44058)
[2024-01-13T15:38:56.320+0200] {local_task_job_runner.py:234} INFO - Task exited with return code 1
[2024-01-13T15:38:56.339+0200] {taskinstance.py:3281} INFO - 0 downstream tasks scheduled from follow-on schedule check
